Workbook

Sheet Cover
B2: Project Harbor
B3: Salesforce buying HubSpot, valuation and deal analysis SIMULATION
B4: As if it would happen on May 2026
B6: What's in this workbook?
B7: This workbook estimates what Salesforce would pay to acquire HubSpot, where the value comes from, and what happens to Salesforce's earnings after the deal. Every number can be changed on the Assumptions tab and the whole model recalculates automatically.
B12: Headline numbers
B13: Offer price per share | C13: =Assumptions!C8 -> 300
B14: Recent average share price | C14: =Assumptions!C9 -> 239.28
B15: Premium being paid | C15: =Assumptions!C12 -> 0.25376128
B16: Total shares being bought (millions) | C16: =Assumptions!C10 -> 52.33
B17: Total cost (millions $) | C17: =Assumptions!C11 -> 15699
B18: Enterprise value (millions $) | C18: =Assumptions!C14 -> 13799
B19: Price vs. revenue multiple | C19: =Assumptions!C20 -> 3.7244265
B21: Guide to the tabs | C21: Explanation of each tab
B22: Assumptions | C22: Every input researched is found here.
B23: Target Financials | C23: HubSpot's actual past performance (sales, profits, customers) and projections.
B24: Trading Comps | C24: Other public software companies similar to HubSpot, used as price reference points.
B25: Precedent Trans | C25: Past acquisitions of similar software companies, used as deal reference points.
B26: Beta Unlever | C26: Calculates how risky HubSpot's stock is, based on similar companies.
B27: DCF | C27: Estimates HubSpot's value by adding up all the cash it will generate in the future.
B28: DCF Sensitivity | C28: Shows how the DCF value changes if key assumptions move up or down.
B29: Synergies | C29: Estimates the extra revenue and cost savings Salesforce gets from owning HubSpot.
B30: Sources & Uses | C30: How Salesforce will pay for the deal (debt, stock, cash) and where the money goes.
B31: Purchase Price Alloc | C31: Accounting allocation of the price paid across the assets being acquired.
B32: Premiums Paid | C32: Comparison of the offer price to recent stock prices and past deal premiums.
... B37: Appendix | C37: Extra peer data and a statistical regression supporting the price analysis.

Sheet Assumptions
B2: ASSUMPTIONS & KEY INPUTS
B5: OFFER & STRUCTURE
C7: Value | D7: Note
B8: Proposed Offer Price ($/share) | C8: 300 | D8: Negotiated offer
B9: 30-Day VWAP ($/share) | C9: 239.28 | D9: HUBS 30-day VWAP, May 2026
B10: Diluted Shares Outstanding (M) | C10: 52.33 | D10: HUBS Q1'26 10-Q diluted share count
B11: Implied Equity Value ($M) | C11: =C8*C10 -> 15699 | D11: Offer × Diluted Shares
B12: Premium to 30-Day VWAP | C12: =C8/C9-1 -> 0.25376128 | D12: ($300 / $239.28) − 1
B13: Net Cash & Equivalents ($M) | C13: 1900 | D13: HUBS Q1'26 cash less debt
B14: Implied Enterprise Value ($M) | C14: =C11-C13 -> 13799 | D14: Equity Value − Net Cash
B16: TARGET REVENUE (Source: 'Target Financials')
B18: FY2025A Revenue ($M) | C18: ='Target Financials'!E7 -> 3131 | D18: Link to financials sheet
B19: FY2026E Revenue ($M) | C19: ='Target Financials'!F7 -> 3705 | D19: Link (consensus estimate)
B20: EV / FY2026E Revenue | C20: =C14/C19 -> 3.7244265 | D20: Implied transaction multiple
B21: EV / FY2025A Revenue (LTM proxy) | C21: =C14/C18 -> 4.4072181
B23: CONSIDERATION MIX
B24: Cash Consideration % of Equity Value | C24: 0.7 | D24: Negotiated mix
B25: Stock Consideration % of Equity Value | C25: =1-C24 -> 0.3 | D25: 1 − cash %
B26: Cash Consideration ($M) | C26: =C11*C24 -> 10989.3
B27: Stock Consideration ($M) | C27: =C11*C25 -> 4709.7
B28: CRM 30-Day VWAP ($/share) | C28: 246 | D28: CRM stock price for stock issuance
B29: New CRM Shares Issued (M) | C29: =C27/C28 -> 19.145122 | D29: Stock consideration / CRM VWAP
B31: DEBT FINANCING
B32: New Term Loan ($M) | C32: 8000 | D32: 5-year senior unsecured
B33: Term Loan Interest Rate | C33: 0.052 | D33: Investment-grade pricing
B34: Annual Interest Expense ($M) | C34: =C32*C33 -> 416 | D34: Debt × rate
B35: One-time Integration Costs Y1 ($M) | C35: 350 | D35: Severance, systems, branding, migration
B37: DCF INPUTS
B38: Risk-Free Rate (10Y UST) | C38: 0.043 | D38: May 2026 10Y Treasury
B39: Equity Risk Premium | C39: 0.055 | D39: Damodaran ERP estimate
B40: Beta (HUBS) | C40: 1.1 | D40: Bloomberg 2Y weekly beta
B41: Cost of Equity (CAPM) | C41: =C38+C40*C39 -> 0.1035 | D41: Rf + β × ERP
B42: Cost of Debt (pre-tax) | C42: 0.052 | D42: Same as term loan rate
B43: Effective Tax Rate | C43: 0.21 | D43: U.S. blended federal + state
B44: Cost of Debt (after-tax) | C44: =C42*(1-C43) -> 0.04108 | D44: Kd × (1 − t)
B45: Equity Weight | C45: 0.95 | D45: Target capital structure
B46: Debt Weight | C46: =1-C45 -> 0.05 | D46: 1 − equity weight
B47: WACC | C47: =C45*C41+C46*C44 -> 0.100379 | D47: we×Ke + wd×Kd×(1−t)
B48: Terminal Growth Rate | C48: 0.04 | D48: Durable SaaS subscription economics
B49: D&A as % of Revenue | C49: 0.03 | D49: Asset-light SaaS infrastructure
...

Sheet Target Financials
B2: HUBSPOT, INC., FINANCIAL HISTORY & FORECAST
B5: INCOME STATEMENT, HISTORICAL & PROJECTED
B6: Metric | C6: FY2023A | D6: FY2024A | E6: FY2025A | F6: FY2026E | G6: FY2027E | H6: FY2028E | I6: FY2029E | J6: FY2030E | K6: FY2031E | L6: FY2032E | M6: FY2033E
B7: Revenue | C7: 2170 | D7: 2628 | E7: 3131 | F7: 3705 | G7: =F7*(1+G9) -> 4338.555 | H7: =G7*(1+H9) -> 5028.3852 | I7: =H7*(1+I9) -> 5732.3592 | J7: =I7*(1+J9) -> 6420.2423 | K7: =J7*(1+K9) -> 7062.2665 | L7: =K7*(1+L9) -> 7627.2478 | M7: =L7*(1+M9) -> 8084.8827
B8: Revenue Growth % | D8: =D7/C7-1 -> 0.21105991 | E8: =E7/D7-1 -> 0.1914003 | F8: =F7/E7-1 -> 0.18332801 | G8: =G7/F7-1 -> 0.171 | H8: =H7/G7-1 -> 0.159 | I8: =I7/H7-1 -> 0.14 | J8: =J7/I7-1 -> 0.12 | K8: =K7/J7-1 -> 0.1 | ... M8: =M7/L7-1 -> 0.06
B9: Forward Growth Assumption | G9: 0.171 | H9: 0.159 | I9: 0.14 | J9: 0.12 | K9: 0.1 | L9: 0.08 | M9: 0.06
B10: Non-GAAP Gross Margin % | C10: 0.83 | D10: 0.84 | E10: 0.85 | F10: 0.86
B11: Non-GAAP Op. Margin % | C11: 0.11 | D11: 0.18 | E11: 0.19 | F11: 0.2 | G11: 0.21 | H11: 0.22 | I11: 0.23 | J11: 0.24 | K11: 0.25 | L11: 0.26 | M11: 0.27
B12: Non-GAAP Op. Income | C12: =C7*C11 -> 238.7 | D12: =D7*D11 -> 473.04 | E12: =E7*E11 -> 594.89 | F12: =F7*F11 -> 741 | G12: =G7*G11 -> 911.09655 | H12: =H7*H11 -> 1106.2448 | I12: =I7*I11 -> 1318.4426 | J12: =J7*J11 -> 1540.8581 | ... M12: =M7*M11 -> 2182.9183
B13: Total Customers (000) | C13: 177 | D13: 216.84 | E13: 248 | F13: 280
B14: Net Dollar Retention % | C14: 1.07 | D14: 1.06 | E14: 1.05 | F14: 1.05
B16: Notes:
B17: • Revenue actuals from HubSpot 10-K filings (FY2023 to FY2025). FY2026E from consensus analyst estimates as of May 2026.
B18: • Forward years driven by growth-rate assumptions in row 9 (yellow). Adjust to flex the DCF.
B19: • Operating margin glide path reflects fixed-cost leverage at scale: 20% (FY26E) → 27% (FY33E).
B20: • D&A and CapEx are each ~3% of revenue (set on Assumptions tab). Net working capital is held flat (deferred revenue offsets AR).
B21: • Non-GAAP figures exclude SBC and amortization of acquired intangibles.

Sheet Trading Comps
B2: TRADING COMPARABLES, PUBLIC SAAS PEER SET
B5: PUBLIC SAAS PEER SET
B6: Company | C6: Mkt Cap ($M) | D6: EV ($M) | E6: NTM Rev ($M) | F6: Rev Gr. % | G6: GM % | H6: EV / NTM Rev
B7: Salesforce (CRM) | C7: 253000 | D7: 247000 | E7: 45700 | F7: 0.1 | G7: 0.78 | H7: =D7/E7 -> 5.404814
B8: ServiceNow (NOW) | C8: 198000 | D8: 196000 | E8: 13500 | F8: 0.19 | G8: 0.8 | H8: =D8/E8 -> 14.518519
B9: Freshworks (FRSH) | C9: 5800 | D9: 4900 | E9: 1070 | F9: 0.16 | G9: 0.83 | H9: =D9/E9 -> 4.5794393
B10: monday.com (MNDY) | C10: 11500 | D10: 10800 | E10: 1620 | F10: 0.22 | G10: 0.89 | H10: =D10/E10 -> 6.6666667
B11: Zendesk (PE-Owned) | C11: N/A | D11: 10200 | E11: 1730 | F11: 0.15 | G11: 0.77 | H11: =D11/E11 -> 5.8959538
B12: Braze (BRZE) | C12: 3200 | D12: 2900 | E12: 590 | F12: 0.21 | G12: 0.69 | H12: =D12/E12 -> 4.9152542
B13: Sprout Social (SPT) | C13: 2100 | D13: 2200 | E13: 420 | F13: 0.18 | G13: 0.74 | H13: =D13/E13 -> 5.2380952
B14: Peer Median | C14: , | D14: =MEDIAN(D7:D13) -> 10200 | E14: =MEDIAN(E7:E13) -> 1620 | F14: =MEDIAN(F7:F13) -> 0.18 | G14: =MEDIAN(G7:G13) -> 0.78 | H14: =MEDIAN(H7:H13) -> 5.404814
B15: HubSpot (HUBS), Current | C15: 12600 | D15: 10800 | E15: 3710 | F15: 0.18 | G15: 0.85 | H15: =D15/E15 -> 2.9110512
B17: IMPLIED VALUATION AT PEER MULTIPLES (HUBS)
B18: Methodology | C18: Multiple Low | D18: Multiple High | E18: Implied EV Low ($M) | F18: Implied EV High ($M) | G18: Implied $/Share Low | H18: Implied $/Share High
B19: EV / NTM Revenue (peer median ± range) | C19: 4 | D19: 6 | E19: =C19*E15 -> 14840 | F19: =D19*E15 -> 22260 | G19: =(E19+Assumptions!C13)/Assumptions!C10 -> 319.89299 | H19: =(F19+Assumptions!C13)/Assumptions!C10 -> 461.68546
B21: HUBS discount to peer median EV/NTM Rev | C21: =H15/H14-1 -> -0.4613966
B23: Notes:
B24: • Peer set selected for comparable end-market exposure (CRM/marketing/customer-engagement SaaS).
B25: • Implied $/share = (Implied EV + Net Cash) / Diluted Shares, properly bridges EV to equity.
B26: • Multiple range (4.0x to 6.0x) sits modestly below peer median to reflect HUBS's slightly lower growth.
B27: • Zendesk taken private 2023 (Permira/H&F); EV reflects take-private transaction value.

Sheet Precedent Trans
B2: PRECEDENT M&A TRANSACTIONS, SAAS / CRM
B5: TRANSACTION COMPARABLES
B6: Acquirer | C6: Target | D6: Year | E6: EV ($M) | F6: EV / LTM Rev | G6: EV / NTM Rev | H6: Premium to VWAP
B7: Salesforce | C7: Slack Technologies | D7: 2021 | E7: 27700 | F7: 26 | G7: 19.5 | H7: 0.55
B8: Salesforce | C8: Tableau Software | D8: 2019 | E8: 15700 | F8: 10.5 | G8: 9.2 | H8: 0.42
B9: Permira/H&F | C9: Zendesk | D9: 2023 | E9: 10200 | F9: 5.9 | G9: 5.4 | H9: 0.34
B10: SAP | C10: Qualtrics | D10: 2019 | E10: 8000 | F10: 20 | G10: 15.4 | H10: 0.38
B11: Thoma Bravo | C11: Ping Identity | D11: 2022 | E11: 2800 | F11: 8.4 | G11: 7.7 | H11: 0.63
B12: Salesforce | C12: Informatica | D12: 2025 | E12: 8000 | F12: 4.7 | G12: 4.4 | H12: 0.28
B13: Salesforce | C13: Own Company | D13: 2024 | E13: 1900 | F13: 6.3 | G13: 5.8 | H13: ,
B14: Median | C14: , | D14: , | E14: =MEDIAN(E7:E13) -> 8000 | F14: =MEDIAN(F7:F13) -> 8.4 | G14: =MEDIAN(G7:G13) -> 7.7 | H14: =MEDIAN(H7:H13) -> 0.4
B15: Salesforce (Proposed) | C15: HubSpot | D15: 2026 | E15: =Assumptions!C14 -> 13799 | F15: =E15/Assumptions!C18 -> 4.4072181 | G15: =E15/Assumptions!C19 -> 3.7244265 | H15: =Assumptions!C12 -> 0.25376128
B17: IMPLIED VALUATION AT PRECEDENT MULTIPLES
B18: Methodology | C18: Multiple Low | D18: Multiple High | E18: Implied EV Low ($M) | F18: Implied EV High ($M) | G18: Implied $/Share Low | H18: Implied $/Share High
B19: EV / NTM Revenue (precedent range) | C19: 5 | D19: 9 | E19: =C19*Assumptions!C19 -> 18525 | F19: =D19*Assumptions!C19 -> 33345 | G19: =(E19+Assumptions!C13)/Assumptions!C10 -> 390.31148 | H19: =(F19+Assumptions!C13)/Assumptions!C10 -> 673.51424
B22: Notes:
B23: • Median premium computed from 6 transactions with disclosed VWAP premiums (Own Company excluded).
B24: • Proposed transaction implies 4.4x LTM and 3.7x NTM, well below precedent medians (8.4x / 7.7x).
B25: • Discount reflects post-2022 SaaS multiple compression environment.

Sheet DCF
B2: DISCOUNTED CASH FLOW ANALYSIS
B5: FREE CASH FLOW BUILDUP, UNLEVERED, AFTER-TAX (SBC treated as real expense)
B6: ($M) | C6: FY2026E | D6: FY2027E | E6: FY2028E | F6: FY2029E | G6: FY2030E | H6: FY2031E | I6: FY2032E | J6: FY2033E
B7: Revenue | C7: ='Target Financials'!F7 -> 3705 | D7: ='Target Financials'!G7 -> 4338.555 | E7: ='Target Financials'!H7 -> 5028.3852 | F7: ='Target Financials'!I7 -> 5732.3592 | G7: ='Target Financials'!J7 -> 6420.2423 | H7: ='Target Financials'!K7 -> 7062.2665 | I7: ='Target Financials'!L7 -> 7627.2478 | J7: ='Target Financials'!M7 -> 8084.8827
B8: YoY growth | D8: =D7/C7-1 -> 0.171 | E8: =E7/D7-1 -> 0.159 | F8: =F7/E7-1 -> 0.14 | G8: =G7/F7-1 -> 0.12 | H8: =H7/G7-1 -> 0.1 | I8: =I7/H7-1 -> 0.08 | J8: =J7/I7-1 -> 0.06
B9: Non-GAAP Op Margin | C9: ='Target Financials'!F11 -> 0.2 | D9: ='Target Financials'!G11 -> 0.21 | E9: ='Target Financials'!H11 -> 0.22 | F9: ='Target Financials'!I11 -> 0.23 | G9: ='Target Financials'!J11 -> 0.24 | H9: ='Target Financials'!K11 -> 0.25 | I9: ='Target Financials'!L11 -> 0.26 | J9: ='Target Financials'!M11 -> 0.27
B10: Non-GAAP EBIT | C10: =C7*C9 -> 741 | D10: =D7*D9 -> 911.09655 | E10: =E7*E9 -> 1106.2448 | F10: =F7*F9 -> 1318.4426 | G10: =G7*G9 -> 1540.8581 | H10: =H7*H9 -> 1765.5666 | I10: =I7*I9 -> 1983.0844 | J10: =J7*J9 -> 2182.9183
B11: (−) SBC % of Revenue | C11: =Assumptions!$C$64+(Assumptions!$C$65-Assumptions!$C$64)*0/7 -> 0.13 | D11: =Assumptions!$C$64+(Assumptions!$C$65-Assumptions!$C$64)*1/7 -> 0.12285714 | E11: =Assumptions!$C$64+(Assumptions!$C$65-Assumptions!$C$64)*2/7 -> 0.11571429 | F11: =Assumptions!$C$64+(Assumptions!$C$65-Assumptions!$C$64)*3/7 -> 0.10857143 | G11: =Assumptions!$C$64+(Assumptions!$C$65-Assumptions!$C$64)*4/7 -> 0.10142857 | H11: =Assumptions!$C$64+(Assumptions!$C$65-Assumptions!$C$64)*5/7 -> 0.094285714 | I11: =Assumptions!$C$64+(Assumptions!$C$65-Assumptions!$C$64)*6/7 -> 0.087142857 | J11: =Assumptions!$C$64+(Assumptions!$C$65-Assumptions!$C$64)*7/7 -> 0.08
B12: (−) SBC expense | C12: =-C7*C11 -> -481.65 | D12: =-D7*D11 -> -533.02247 | E12: =-E7*E11 -> -581.85601 | F12: =-F7*F11 -> -622.37043 | G12: =-G7*G11 -> -651.196 | H12: =-H7*H11 -> -665.87084 | I12: =-I7*I11 -> -664.66017 | J12: =-J7*J11 -> -646.79062
B13: Adjusted EBIT (post-SBC) | C13: =C10+C12 -> 259.35 | D13: =D10+D12 -> 378.07408 | E13: =E10+E12 -> 524.38875 | F13: =F10+F12 -> 696.07219 | G13: =G10+G12 -> 889.66214 | H13: =H10+H12 -> 1099.6958 | I13: =I10+I12 -> 1318.4243 | J13: =J10+J12 -> 1536.1277
B14: (−) Tax @ effective rate | C14: =-C13*Assumptions!$C$43 -> -54.4635 | D14: =-D13*Assumptions!$C$43 -> -79.395556 | E14: =-E13*Assumptions!$C$43 -> -110.12164 | F14: =-F13*Assumptions!$C$43 -> -146.17516 | G14: =-G13*Assumptions!$C$43 -> -186.82905 | H14: =-H13*Assumptions!$C$43 -> -230.93611 | I14: =-I13*Assumptions!$C$43 -> -276.8691 | J14: =-J13*Assumptions!$C$43 -> -322.58682
B15: NOPAT | C15: =C13+C14 -> 204.8865 | D15: =D13+D14 -> 298.67852 | E15: =E13+E14 -> 414.26711 | F15: =F13+F14 -> 549.89703 | G15: =G13+G14 -> 702.83309 | H15: =H13+H14 -> 868.75967 | I15: =I13+I14 -> 1041.5552 | J15: =J13+J14 -> 1213.5409
B16: (+) D&A | C16: =C7*Assumptions!$C$49 -> 111.15 | D16: =D7*Assumptions!$C$49 -> 130.15665 | E16: =E7*Assumptions!$C$49 -> 150.85156 | F16: =F7*Assumptions!$C$49 -> 171.97078 | G16: =G7*Assumptions!$C$49 -> 192.60727 | H16: =H7*Assumptions!$C$49 -> 211.868 | I16: =I7*Assumptions!$C$49 -> 228.81743 | J16: =J7*Assumptions!$C$49 -> 242.54648
B17: (−) CapEx | C17: =-C7*Assumptions!$C$50 -> -111.15 | D17: =-D7*Assumptions!$C$50 -> -130.15665 | E17: =-E7*Assumptions!$C$50 -> -150.85156 | F17: =-F7*Assumptions!$C$50 -> -171.97078 | G17: =-G7*Assumptions!$C$50 -> -192.60727 | H17: =-H7*Assumptions!$C$50 -> -211.868 | I17: =-I7*Assumptions!$C$50 -> -228.81743 | J17: =-J7*Assumptions!$C$50 -> -242.54648
B18: NWC ($, level) | C18: =C7*Assumptions!$C$72 -> -1111.5 | D18: =D7*Assumptions!$C$72 -> -1301.5665 | E18: =E7*Assumptions!$C$72 -> -1508.5156 | F18: =F7*Assumptions!$C$72 -> -1719.7078 | G18: =G7*Assumptions!$C$72 -> -1926.0727 | H18: =H7*Assumptions!$C$72 -> -2118.68 | I18: =I7*Assumptions!$C$72 -> -2288.1743 | J18: =J7*Assumptions!$C$72 -> -2425.4648
B19: (−) ΔNWC (growth-driven) | C19: =-(C7-'Target Financials'!E7)*Assumptions!$C$72 -> 172.2 | D19: =-(D18-C18) -> 190.0665 | E19: =-(E18-D18) -> 206.94907 | F19: =-(F18-E18) -> 211.19218 | G19: =-(G18-F18) -> 206.36493 | H19: =-(H18-G18) -> 192.60727 | I19: =-(I18-H18) -> 169.4944 | J19: =-(J18-I18) -> 137.29046
B20: Unlevered Free Cash Flow | C20: =C15+C16+C17+C19 -> 377.0865 | D20: =D15+D16+D17+D19 -> 488.74502 | E20: =E15+E16+E17+E19 -> 621.21618 | F20: =F15+F16+F17+F19 -> 761.08921 | G20: =G15+G16+G17+G19 -> 909.19802 | H20: =H15+H16+H17+H19 -> 1061.3669 | I20: =I15+I16+I17+I19 -> 1211.0496 | J20: =J15+J16+J17+J19 -> 1350.8314
B21: Discount period (year-end) | C21: 1 | D21: 2 | E21: 3 | F21: 4 | G21: 5 | H21: 6 | I21: 7 | J21: 8
B22: Discount factor | C22: =1/(1+Assumptions!$C$47)^C21 -> 0.90877779 | D22: =1/(1+Assumptions!$C$47)^D21 -> 0.82587708 | E22: =1/(1+Assumptions!$C$47)^E21 -> 0.75053875 | F22: =1/(1+Assumptions!$C$47)^F21 -> 0.68207295 | G22: =1/(1+Assumptions!$C$47)^G21 -> 0.61985275 | H22: =1/(1+Assumptions!$C$47)^H21 -> 0.56330841 | I22: =1/(1+Assumptions!$C$47)^I21 -> 0.51192218 | J22: =1/(1+Assumptions!$C$47)^J21 -> 0.46522351
B23: PV of FCF | C23: =C20*C22 -> 342.68784 | D23: =D20*D22 -> 403.64331 | E23: =E20*E22 -> 466.24682 | F23: =F20*F22 -> 519.11836 | G23: =G20*G22 -> 563.5689 | H23: =H20*H22 -> 597.87693 | I23: =I20*I22 -> 619.96313 | J23: =J20*J22 -> 628.4385
B26: VALUATION SUMMARY
B28: Sum of PV of explicit FCFs ($M) | C28: =SUM(C23:J23) -> 4141.5438
B29: Terminal year FCF (FY2033E) | C29: =J20 -> 1350.8314
B30: Terminal growth rate | C30: =Assumptions!C48 -> 0.04
B31: WACC | C31: =Assumptions!C47 -> 0.100379
B32: Terminal Value (Gordon Growth) | C32: =J20*(1+C30)/(C31-C30) -> 23267.437
B33: PV of Terminal Value | C33: =C32*J22 -> 10824.559
B34: Implied Enterprise Value ($M) | C34: =C28+C33 -> 14966.103
B35: (+) Net cash | C35: =Assumptions!C13 -> 1900
B36: Implied Equity Value ($M) | C36: =C34+C35 -> 16866.103
B37: Diluted shares (M) | C37: =Assumptions!C10 -> 52.33
B38: Implied Price per Share ($) | C38: =C36/C37 -> 322.30275
B39: Proposed Offer Price | C39: =Assumptions!C8 -> 300
B40: Premium / (Discount) of offer to DCF | C40: =C39/C38-1 -> -0.069198124
B43: How to read this tab:
B44: • Stock-based compensation is treated as a real cost. Even though companies often exclude it from non-GAAP figures, it dilutes shareholders.
B45: • Working capital is a source of cash for SaaS due to deferred revenue exceeding AR, captured in ΔNWC line.
B46: • D&A and CapEx held at 3% of revenue (offsetting); ΔNWC = NWC% × revenue growth.
B47: • Cash flows are discounted assuming they arrive at the end of each year.
B48: • Terminal value via Gordon Growth: FCF_2033 × (1+TGR) / (WACC−TGR).
...

Sheet DCF Sensitivity
B2: DCF SENSITIVITY, IMPLIED $/SHARE
B6: WACC × TERMINAL GROWTH RATE → IMPLIED $/SHARE
B8: WACC ↓ / TGR → | C8: 0.025 | D8: 0.03 | E8: 0.035 | F8: 0.04 | G8: 0.045 | H8: 0.05
B9: 0.085 | C9: =(SUMPRODUCT(DCF!$C$20:$J$20/(1+$B9)^DCF!$C$21:$J$21)+(DCF!$J$20*(1+C$8)/($B9-C$8))/(1+$B9)^DCF!$J$21+Assumptions!$C$13)/Assumptions!$C$10 -> 350.77951 | D9: =(SUMPRODUCT(DCF!$C$20:$J$20/(1+$B9)^DCF!$C$21:$J$21)+(DCF!$J$20*(1+D$8)/($B9-D$8))/(1+$B9)^DCF!$J$21+Assumptions!$C$13)/Assumptions!$C$10 -> 372.87473 | E9: =(SUMPRODUCT(DCF!$C$20:$J$20/(1+$B9)^DCF!$C$21:$J$21)+(DCF!$J$20*(1+E$8)/($B9-E$8))/(1+$B9)^DCF!$J$21+Assumptions!$C$13)/Assumptions!$C$10 -> 399.38899 | F9: =(SUMPRODUCT(DCF!$C$20:$J$20/(1+$B9)^DCF!$C$21:$J$21)+(DCF!$J$20*(1+F$8)/($B9-F$8))/(1+$B9)^DCF!$J$21+Assumptions!$C$13)/Assumptions!$C$10 -> 431.79531 | G9: =(SUMPRODUCT(DCF!$C$20:$J$20/(1+$B9)^DCF!$C$21:$J$21)+(DCF!$J$20*(1+G$8)/($B9-G$8))/(1+$B9)^DCF!$J$21+Assumptions!$C$13)/Assumptions!$C$10 -> 472.30321 | H9: =(SUMPRODUCT(DCF!$C$20:$J$20/(1+$B9)^DCF!$C$21:$J$21)+(DCF!$J$20*(1+H$8)/($B9-H$8))/(1+$B9)^DCF!$J$21+Assumptions!$C$13)/Assumptions!$C$10 -> 524.38479
B10: 0.09 | C10: =(SUMPRODUCT(DCF!$C$20:$J$20/(1+$B10)^DCF!$C$21:$J$21)+(DCF!$J$20*(1+C$8)/($B10-C$8))/(1+$B10)^DCF!$J$21+Assumptions!$C$13)/Assumptions!$C$10 -> 323.54143 | D10: =(SUMPRODUCT(DCF!$C$20:$J$20/(1+$B10)^DCF!$C$21:$J$21)+(DCF!$J$20*(1+D$8)/($B10-D$8))/(1+$B10)^DCF!$J$21+Assumptions!$C$13)/Assumptions!$C$10 -> 341.64525 | E10: =(SUMPRODUCT(DCF!$C$20:$J$20/(1+$B10)^DCF!$C$21:$J$21)+(DCF!$J$20*(1+E$8)/($B10-E$8))/(1+$B10)^DCF!$J$21+Assumptions!$C$13)/Assumptions!$C$10 -> 363.04068 | F10: =(SUMPRODUCT(DCF!$C$20:$J$20/(1+$B10)^DCF!$C$21:$J$21)+(DCF!$J$20*(1+F$8)/($B10-F$8))/(1+$B10)^DCF!$J$21+Assumptions!$C$13)/Assumptions!$C$10 -> 388.71519 | G10: =(SUMPRODUCT(DCF!$C$20:$J$20/(1+$B10)^DCF!$C$21:$J$21)+(DCF!$J$20*(1+G$8)/($B10-G$8))/(1+$B10)^DCF!$J$21+Assumptions!$C$13)/Assumptions!$C$10 -> 420.09515 | H10: =(SUMPRODUCT(DCF!$C$20:$J$20/(1+$B10)^DCF!$C$21:$J$21)+(DCF!$J$20*(1+H$8)/($B10-H$8))/(1+$B10)^DCF!$J$21+Assumptions!$C$13)/Assumptions!$C$10 -> 459.3201
B11: 0.095 | C11: =(SUMPRODUCT(DCF!$C$20:$J$20/(1+$B11)^DCF!$C$21:$J$21)+(DCF!$J$20*(1+C$8)/($B11-C$8))/(1+$B11)^DCF!$J$21+Assumptions!$C$13)/Assumptions!$C$10 -> 300.26768 | D11: =(SUMPRODUCT(DCF!$C$20:$J$20/(1+$B11)^DCF!$C$21:$J$21)+(DCF!$J$20*(1+D$8)/($B11-D$8))/(1+$B11)^DCF!$J$21+Assumptions!$C$13)/Assumptions!$C$10 -> 315.29599 | E11: =(SUMPRODUCT(DCF!$C$20:$J$20/(1+$B11)^DCF!$C$21:$J$21)+(DCF!$J$20*(1+E$8)/($B11-E$8))/(1+$B11)^DCF!$J$21+Assumptions!$C$13)/Assumptions!$C$10 -> 332.82902 | F11: =(SUMPRODUCT(DCF!$C$20:$J$20/(1+$B11)^DCF!$C$21:$J$21)+(DCF!$J$20*(1+F$8)/($B11-F$8))/(1+$B11)^DCF!$J$21+Assumptions!$C$13)/Assumptions!$C$10 -> 353.54987 | G11: =(SUMPRODUCT(DCF!$C$20:$J$20/(1+$B11)^DCF!$C$21:$J$21)+(DCF!$J$20*(1+G$8)/($B11-G$8))/(1+$B11)^DCF!$J$21+Assumptions!$C$13)/Assumptions!$C$10 -> 378.4149 | H11: =(SUMPRODUCT(DCF!$C$20:$J$20/(1+$B11)^DCF!$C$21:$J$21)+(DCF!$J$20*(1+H$8)/($B11-H$8))/(1+$B11)^DCF!$J$21+Assumptions!$C$13)/Assumptions!$C$10 -> 408.80548
B12: 0.1 | C12: =(SUMPRODUCT(DCF!$C$20:$J$20/(1+$B12)^DCF!$C$21:$J$21)+(DCF!$J$20*(1+C$8)/($B12-C$8))/(1+$B12)^DCF!$J$21+Assumptions!$C$13)/Assumptions!$C$10 -> 280.16318 | D12: =(SUMPRODUCT(DCF!$C$20:$J$20/(1+$B12)^DCF!$C$21:$J$21)+(DCF!$J$20*(1+D$8)/($B12-D$8))/(1+$B12)^DCF!$J$21+Assumptions!$C$13)/Assumptions!$C$10 -> 292.77891 | E12: =(SUMPRODUCT(DCF!$C$20:$J$20/(1+$B12)^DCF!$C$21:$J$21)+(DCF!$J$20*(1+E$8)/($B12-E$8))/(1+$B12)^DCF!$J$21+Assumptions!$C$13)/Assumptions!$C$10 -> 307.33552 | F12: =(SUMPRODUCT(DCF!$C$20:$J$20/(1+$B12)^DCF!$C$21:$J$21)+(DCF!$J$20*(1+F$8)/($B12-F$8))/(1+$B12)^DCF!$J$21+Assumptions!$C$13)/Assumptions!$C$10 -> 324.31823 | G12: =(SUMPRODUCT(DCF!$C$20:$J$20/(1+$B12)^DCF!$C$21:$J$21)+(DCF!$J$20*(1+G$8)/($B12-G$8))/(1+$B12)^DCF!$J$21+Assumptions!$C$13)/Assumptions!$C$10 -> 344.3887 | H12: =(SUMPRODUCT(DCF!$C$20:$J$20/(1+$B12)^DCF!$C$21:$J$21)+(DCF!$J$20*(1+H$8)/($B12-H$8))/(1+$B12)^DCF!$J$21+Assumptions!$C$13)/Assumptions!$C$10 -> 368.47327
B13: 0.105 | C13: =(SUMPRODUCT(DCF!$C$20:$J$20/(1+$B13)^DCF!$C$21:$J$21)+(DCF!$J$20*(1+C$8)/($B13-C$8))/(1+$B13)^DCF!$J$21+Assumptions!$C$13)/Assumptions!$C$10 -> 262.63168 | D13: =(SUMPRODUCT(DCF!$C$20:$J$20/(1+$B13)^DCF!$C$21:$J$21)+(DCF!$J$20*(1+D$8)/($B13-D$8))/(1+$B13)^DCF!$J$21+Assumptions!$C$13)/Assumptions!$C$10 -> 273.32551 | E13: =(SUMPRODUCT(DCF!$C$20:$J$20/(1+$B13)^DCF!$C$21:$J$21)+(DCF!$J$20*(1+E$8)/($B13-E$8))/(1+$B13)^DCF!$J$21+Assumptions!$C$13)/Assumptions!$C$10 -> 285.54703 | F13: =(SUMPRODUCT(DCF!$C$20:$J$20/(1+$B13)^DCF!$C$21:$J$21)+(DCF!$J$20*(1+F$8)/($B13-F$8))/(1+$B13)^DCF!$J$21+Assumptions!$C$13)/Assumptions!$C$10 -> 299.64878 | G13: =(SUMPRODUCT(DCF!$C$20:$J$20/(1+$B13)^DCF!$C$21:$J$21)+(DCF!$J$20*(1+G$8)/($B13-G$8))/(1+$B13)^DCF!$J$21+Assumptions!$C$13)/Assumptions!$C$10 -> 316.10082 | H13: =(SUMPRODUCT(DCF!$C$20:$J$20/(1+$B13)^DCF!$C$21:$J$21)+(DCF!$J$20*(1+H$8)/($B13-H$8))/(1+$B13)^DCF!$J$21+Assumptions!$C$13)/Assumptions!$C$10 -> 335.54415
B14: 0.11 | C14: =(SUMPRODUCT(DCF!$C$20:$J$20/(1+$B14)^DCF!$C$21:$J$21)+(DCF!$J$20*(1+C$8)/($B14-C$8))/(1+$B14)^DCF!$J$21+Assumptions!$C$13)/Assumptions!$C$10 -> 247.21731 | D14: =(SUMPRODUCT(DCF!$C$20:$J$20/(1+$B14)^DCF!$C$21:$J$21)+(DCF!$J$20*(1+D$8)/($B14-D$8))/(1+$B14)^DCF!$J$21+Assumptions!$C$13)/Assumptions!$C$10 -> 256.35951 | E14: =(SUMPRODUCT(DCF!$C$20:$J$20/(1+$B14)^DCF!$C$21:$J$21)+(DCF!$J$20*(1+E$8)/($B14-E$8))/(1+$B14)^DCF!$J$21+Assumptions!$C$13)/Assumptions!$C$10 -> 266.72067 | F14: =(SUMPRODUCT(DCF!$C$20:$J$20/(1+$B14)^DCF!$C$21:$J$21)+(DCF!$J$20*(1+F$8)/($B14-F$8))/(1+$B14)^DCF!$J$21+Assumptions!$C$13)/Assumptions!$C$10 -> 278.56199 | G14: =(SUMPRODUCT(DCF!$C$20:$J$20/(1+$B14)^DCF!$C$21:$J$21)+(DCF!$J$20*(1+G$8)/($B14-G$8))/(1+$B14)^DCF!$J$21+Assumptions!$C$13)/Assumptions!$C$10 -> 292.22506 | H14: =(SUMPRODUCT(DCF!$C$20:$J$20/(1+$B14)^DCF!$C$21:$J$21)+(DCF!$J$20*(1+H$8)/($B14-H$8))/(1+$B14)^DCF!$J$21+Assumptions!$C$13)/Assumptions!$C$10 -> 308.1653
B15: 0.115 | C15: =(SUMPRODUCT(DCF!$C$20:$J$20/(1+$B15)^DCF!$C$21:$J$21)+(DCF!$J$20*(1+C$8)/($B15-C$8))/(1+$B15)^DCF!$J$21+Assumptions!$C$13)/Assumptions!$C$10 -> 233.56556 | D15: =(SUMPRODUCT(DCF!$C$20:$J$20/(1+$B15)^DCF!$C$21:$J$21)+(DCF!$J$20*(1+D$8)/($B15-D$8))/(1+$B15)^DCF!$J$21+Assumptions!$C$13)/Assumptions!$C$10 -> 241.44028 | E15: =(SUMPRODUCT(DCF!$C$20:$J$20/(1+$B15)^DCF!$C$21:$J$21)+(DCF!$J$20*(1+E$8)/($B15-E$8))/(1+$B15)^DCF!$J$21+Assumptions!$C$13)/Assumptions!$C$10 -> 250.29933 | F15: =(SUMPRODUCT(DCF!$C$20:$J$20/(1+$B15)^DCF!$C$21:$J$21)+(DCF!$J$20*(1+F$8)/($B15-F$8))/(1+$B15)^DCF!$J$21+Assumptions!$C$13)/Assumptions!$C$10 -> 260.3396 | G15: =(SUMPRODUCT(DCF!$C$20:$J$20/(1+$B15)^DCF!$C$21:$J$21)+(DCF!$J$20*(1+G$8)/($B15-G$8))/(1+$B15)^DCF!$J$21+Assumptions!$C$13)/Assumptions!$C$10 -> 271.81418 | H15: =(SUMPRODUCT(DCF!$C$20:$J$20/(1+$B15)^DCF!$C$21:$J$21)+(DCF!$J$20*(1+H$8)/($B15-H$8))/(1+$B15)^DCF!$J$21+Assumptions!$C$13)/Assumptions!$C$10 -> 285.05409
B17: Notes:
B18: • Base case (9.5% WACC, 4.0% TGR) highlighted in green. All other cells flex independently.
B19: • Implied $/share rises with lower WACC and higher TGR (and vice versa).
B20: • Across the plausible range, intrinsic value materially exceeds the $300 proposed offer in every cell.

Sheet Synergies
B2: SYNERGY ANALYSIS, REVENUE & COST
B5: REVENUE SYNERGIES
B6: Initiative | C6: Year 1 | D6: Year 2 | E6: Year 3
B7: Cross-sell Salesforce products to HUBS customers | C7: 85 | D7: 210 | E7: 400
B8: HubSpot as SMB on-ramp to Salesforce platform | C8: 45 | D8: 130 | E8: 280
B9: AI product bundling (Agentforce + Breeze AI) | C9: 30 | D9: 90 | E9: 220
B10: International channel leverage | C10: 20 | D10: 55 | E10: 100
B11: Revenue Synergy Subtotal | C11: =SUM(C7:C10) -> 180 | D11: =SUM(D7:D10) -> 485 | E11: =SUM(E7:E10) -> 1000
B13: COST SYNERGIES
B14: Initiative | C14: Year 1 | D14: Year 2 | E14: Year 3
B15: Infrastructure & cloud platform consolidation | C15: 45 | D15: 110 | E15: 180
B16: Duplicate G&A and corporate overhead elimination | C16: 60 | D16: 120 | E16: 180
B17: Vendor and procurement consolidation | C17: 25 | D17: 55 | E17: 80
B18: Cost Synergy Subtotal | C18: =SUM(C15:C17) -> 130 | D18: =SUM(D15:D17) -> 285 | E18: =SUM(E15:E17) -> 440
B20: TOTAL SYNERGIES (Revenue + Cost) | C20: =C11+C18 -> 310 | D20: =D11+D18 -> 770 | E20: =E11+E18 -> 1440
B23: CROSS-SELL SYNERGY, BOTTOM-UP CHECK
B24: HubSpot Customer Base (000) | C24: 248
B25: Cross-sell Attach Rate (Y3 steady-state) | C25: 0.135
B26: Average Incremental ACV ($) | C26: 12000
B27: Implied Cross-sell ARR ($M) | C27: =C24*C25*C26/1000 -> 401.76
B31: Notes:
B32: • Numbers are annual, before tax. Year 3 reflects the full benefit once integration is complete.
B33: • There are $350M of one-time costs in Year 1 to combine the companies. Those are tracked separately, not subtracted here.
B34: • Cross-sell math: 248K customers × 13.5% attach × $12K ACV ≈ $402M, ties to revenue synergy line.

Sheet Football Field
B2: FOOTBALL FIELD, VALUATION SUMMARY
B5: VALUATION METHODOLOGY SUMMARY
B6: Methodology | C6: Low ($/share) | D6: High ($/share) | E6: Midpoint | F6: Source / Note
B7: 52-Week Trading Range | C7: 159 | D7: 317 | E7: =AVERAGE(C7:D7) -> 238 | F7: HUBS 52-week trading range, May 2026
B8: Comparable Companies (4.0x to 6.0x NTM Rev) | C8: ='Trading Comps'!G19 -> 319.89299 | D8: ='Trading Comps'!H19 -> 461.68546 | E8: =AVERAGE(C8:D8) -> 390.78922 | F8: Public peer set, EV+net cash → equity
B9: Precedent Transactions (5.0x to 9.0x NTM Rev) | C9: ='Precedent Trans'!G19 -> 390.31148 | D9: ='Precedent Trans'!H19 -> 673.51424 | E9: =AVERAGE(C9:D9) -> 531.91286 | F9: M&A precedent set, EV+net cash → equity
B10: DCF Analysis (WACC 8.5% to 11.5%, TGR 2.5% to 5.0%) | C10: =MIN('DCF Sensitivity'!C9:H15) -> 233.56556 | D10: =MAX('DCF Sensitivity'!C9:H15) -> 524.38479 | E10: =AVERAGE(C10:D10) -> 378.97518 | F10: Min/max of full sensitivity grid
B11: DCF Base Case (9.5% WACC / 4.0% TGR) | C11: =DCF!C38 -> 322.30275 | D11: =DCF!C38 -> 322.30275 | E11: =DCF!C38 -> 322.30275 | F11: Single-point intrinsic value
B12: PROPOSED OFFER PRICE | C12: =Assumptions!C8 -> 300 | D12: =Assumptions!C12 -> 0.25376128 | E12: =Assumptions!C14 -> 13799 | F12: Offer / Premium / Implied EV
B14: Notes:
B15: • Implied $/share for each methodology = (Implied EV + Net Cash) / Diluted Shares, proper bridge from EV to equity.
B16: • Proposed $300 offer is BELOW the low end of every fundamental valuation method.
B17: • The 52-week trading range reflects recent depressed market prices and isn't a fundamental measure of value.

Sheet Accretion-Dilution
B2: PRO FORMA ACCRETION / DILUTION, GAAP & NON-GAAP
B3: Will the deal increase or decrease Salesforce's earnings per share? Shows both the accounting view (GAAP) and the operational view (non-GAAP) over the first two years.
B5: TRANSACTION STRUCTURE & FINANCING
B7: Implied equity value ($M) | C7: =Assumptions!C11 -> 15699
B8: Cash consideration ($M) | C8: =Assumptions!C26 -> 10989.3
B9: Stock consideration ($M) | C9: =Assumptions!C27 -> 4709.7
B10: New CRM shares issued (M) | C10: =Assumptions!C29 -> 19.145122
B11: New term loan ($M) | C11: =Assumptions!C32 -> 8000
B12: Annual interest expense ($M) | C12: =Assumptions!C34 -> 416
B13: One-time integration costs Y1 | C13: =Assumptions!C35 -> 350
B14: Intangibles amortization Y1 | C14: ='Purchase Price Alloc'!C31 -> 556.66667 | D14: ='Purchase Price Alloc'!D31 -> 556.66667
B15: Deferred revenue write-down | C15: =-'Purchase Price Alloc'!C19 -> -200
B18: NON-GAAP NET INCOME BUILD
B19: ($M) | C19: Year 1 | D19: Year 2
B20: CRM standalone Non-GAAP NI | C20: =Assumptions!C55*Assumptions!C54 -> 11513.6 | D20: =Assumptions!C56*Assumptions!C54 -> 12747.2
B21: (+) HubSpot Non-GAAP NI contribution | C21: =Assumptions!C57 -> 360 | D21: =Assumptions!C58 -> 758
B22: (+) Pre-tax synergies | C22: =Synergies!C20 -> 310 | D22: =Synergies!D20 -> 770
B23: (−) Tax on synergies | C23: =-C22*Assumptions!$C$43 -> -65.1 | D23: =-D22*Assumptions!$C$43 -> -161.7
B24: (−) Integration costs (after-tax) | C24: =-$C$13*(1-Assumptions!$C$43) -> -276.5 | D24: =0 -> 0
B25: (−) Interest expense (after-tax) | C25: =-Assumptions!$C$34*(1-Assumptions!$C$43) -> -328.64 | D25: =-Assumptions!$C$34*(1-Assumptions!$C$43) -> -328.64
B26: Pro forma Non-GAAP Net Income | C26: =SUM(C20:C25) -> 11513.36 | D26: =SUM(D20:D25) -> 13784.86
B29: GAAP ADJUSTMENTS (incremental from Non-GAAP)
C30: Year 1 | D30: Year 2
B31: CRM standalone GAAP NI | C31: 4500 | D31: 5400
B32: (+) HubSpot GAAP NI contribution | C32: 100 | D32: 350
B33: (−) Intangibles amortization (after-tax) | C33: =-'Purchase Price Alloc'!C31*(1-Assumptions!$C$43) -> -439.76667 | D33: =-'Purchase Price Alloc'!D31*(1-Assumptions!$C$43) -> -439.76667
B34: (−) Deferred rev write-down impact (after-tax) | C34: =-200*(1-Assumptions!$C$43) -> -158 | D34: =0 -> 0
B35: (+) Pre-tax synergies | C35: =Synergies!C20 -> 310 | D35: =Synergies!D20 -> 770
B36: (−) Tax on synergies | C36: =-C35*Assumptions!$C$43 -> -65.1 | D36: =-D35*Assumptions!$C$43 -> -161.7
B37: (−) Integration costs (after-tax) | C37: =-$C$13*(1-Assumptions!$C$43) -> -276.5 | D37: =0 -> 0
B38: (−) Interest expense (after-tax) | C38: =-Assumptions!$C$34*(1-Assumptions!$C$43) -> -328.64 | D38: =-Assumptions!$C$34*(1-Assumptions!$C$43) -> -328.64
B39: Pro forma GAAP Net Income | C39: =SUM(C31:C38) -> 3641.9933 | D39: =SUM(D31:D38) -> 5589.8933
B42: EPS COMPARISON
C43: Year 1 | D43: Year 2
B44: Pro forma diluted shares (M) | C44: =Assumptions!C54+Assumptions!C29 -> 1047.1451 | D44: =Assumptions!C54+Assumptions!C29 -> 1047.1451
B46: Non-GAAP Standalone EPS | C46: =Assumptions!C55 -> 11.2 | D46: =Assumptions!C56 -> 12.4
B47: Non-GAAP Pro forma EPS | C47: =C26/C44 -> 10.994999 | D47: =D26/D44 -> 13.164231
B48: Non-GAAP Accretion / (Dilution) | C48: =C47/C46-1 -> -0.018303624 | D48: =D47/D46-1 -> 0.061631511
B50: GAAP Standalone EPS | C50: =C31/Assumptions!C54 -> 4.3774319 | D50: =D31/Assumptions!C54 -> 5.2529183
B51: GAAP Pro forma EPS | C51: =C39/C44 -> 3.4780216 | D51: =D39/D44 -> 5.3382222
...

Sheet Beta Unlever
B2: BETA UNLEVERING & RE-LEVERING (Hamada)
B3: Beta measures how much a stock moves with the overall market. We compute a fair beta for HubSpot by averaging similar companies, which feeds into the discount rate.
B5: COMPARABLE COMPANY BETAS
B6: Company | C6: Levered β | D6: Debt/Equity | E6: Tax rate | F6: Unlevered β
B7: Salesforce (CRM) | C7: 1.05 | D7: 0.05 | E7: 0.21 | F7: =C7/(1+(1-E7)*D7) -> 1.010101
B8: ServiceNow (NOW) | C8: 1.1 | D8: 0.03 | E8: 0.21 | F8: =C8/(1+(1-E8)*D8) -> 1.0745336
B9: Freshworks (FRSH) | C9: 1.15 | D9: 0.02 | E9: 0.21 | F9: =C9/(1+(1-E9)*D9) -> 1.1321126
B10: monday.com (MNDY) | C10: 1.25 | D10: 0.01 | E10: 0.21 | F10: =C10/(1+(1-E10)*D10) -> 1.2402024
B11: Adobe (ADBE) | C11: 1.1 | D11: 0.08 | E11: 0.21 | F11: =C11/(1+(1-E11)*D11) -> 1.0346125
B12: Workday (WDAY) | C12: 1.05 | D12: 0.1 | E12: 0.21 | F12: =C12/(1+(1-E12)*D12) -> 0.97312326
B13: Atlassian (TEAM) | C13: 1.2 | D13: 0.04 | E13: 0.21 | F13: =C13/(1+(1-E13)*D13) -> 1.1632416
B14: Median | C14: =MEDIAN(C7:C13) -> 1.1 | D14: =MEDIAN(D7:D13) -> 0.04 | E14: =MEDIAN(E7:E13) -> 0.21 | F14: =MEDIAN(F7:F13) -> 1.0745336
B16: RE-LEVER FOR HUBS TARGET CAPITAL STRUCTURE
B17: Median unlevered β (industry) | C17: =F14 -> 1.0745336
B18: HUBS target D/E ratio | C18: =Assumptions!C46/Assumptions!C45 -> 0.052631579
B19: HUBS effective tax rate | C19: =Assumptions!C43 -> 0.21
B20: Re-levered β (HUBS) | C20: =C17*(1+(1-C19)*C18) -> 1.1192115
B21: Beta used in DCF (Assumptions!C40) | C21: =Assumptions!C40 -> 1.1
B22: Variance | C22: =C21-C20 -> -0.019211529
B25: How this works:
B26: • Hamada equation: βU = βL / (1 + (1−t) × D/E). Levered betas sourced from Bloomberg 2Y weekly.
B27: • After stripping out debt effects, we take the middle value across similar companies to get a clean industry-wide risk level.
B28: • Re-levering at HUBS target structure (5% debt) produces β ≈ 1.10, supports the Assumptions!C40 input.

Sheet Sources & Uses
B2: SOURCES & USES OF FUNDS
B3: Where Salesforce gets the money to do the deal (debt, stock, cash) and how that money is spent. Sources must equal Uses, which is the balance check at the bottom.
B5: SOURCES
B6: Source | C6: $M | D6: % of total | E6: Note
B7: Term loan (5Y, IG pricing) | C7: =Assumptions!C32 -> 8000 | D7: =C7/$C$11 -> 0.50444543 | E7: 5 year loan at 5.2% interest
B8: CRM stock issuance | C8: =Assumptions!C27 -> 4709.7 | D8: =C8/$C$11 -> 0.29697333 | E8: 30% of the deal value, paid by giving HubSpot shareholders new Salesforce shares at the recent $246 price
B9: Salesforce balance sheet cash | C9: =C20-C7-C8 -> 3149.3 | D9: =C9/$C$11 -> 0.19858125 | E9: Plug: Total uses − Term loan − Stock
B11: Total Sources | C11: =SUM(C7:C10) -> 15859 | D11: =SUM(D7:D10) -> 1
B14: USES
B15: Use | C15: $M | D15: % of total | E15: Note
B16: Equity purchase price | C16: =Assumptions!C11 -> 15699 | D16: =C16/$C$20 -> 0.98991109 | E16: 52.33M shares × $300
B17: Financing fees (1% of debt) | C17: =Assumptions!C32*0.01 -> 80 | D17: =C17/$C$20 -> 0.0050444543 | E17: Bank fees for arranging the loan
B18: Advisory & legal fees | C18: =50 -> 50 | D18: =C18/$C$20 -> 0.0031527839 | E18: Investment banker and legal fees
B19: Other transaction costs | C19: =30 -> 30 | D19: =C19/$C$20 -> 0.0018916703 | E19: Regulatory filings, shareholder communications, and bonuses to keep key HubSpot employees
B20: Total Uses | C20: =SUM(C16:C19) -> 15859
B22: Balance check (Sources − Uses) | C22: =C11-C20 -> 0
B25: PRO FORMA CAPITAL STRUCTURE (Salesforce post-close)
B27: CRM existing debt ($M) | C27: 1000 | E27: Salesforce's existing debt before the deal
B28: (+) New term loan | C28: =Assumptions!C32 -> 8000
B29: Pro forma total debt | C29: =C27+C28 -> 9000
B30: Pro forma cash & equivalents | C30: 7000 | E30: Cash on hand after the deal, roughly $10B before minus $3B used
B31: Pro forma net debt | C31: =C29-C30 -> 2000
B32: Pro forma equity market cap | C32: =253000+Assumptions!C27 -> 257709.7 | E32: Salesforce's current value plus the new shares given to HubSpot shareholders
B33: Pro forma enterprise value | C33: =C31+C32 -> 259709.7
B34: Pro forma net debt / EBITDA | C34: =C31/12000 -> 0.16666667 | E34: Combined company operating profit estimate

Sheet Purchase Price Alloc
B2: PURCHASE PRICE ALLOCATION & INTANGIBLES AMORTIZATION
B3: Accounting rules require us to assign the purchase price across what's being acquired: customer relationships, technology, brand, and leftover goodwill. This affects future earnings.
B5: STEP 1: EXCESS PURCHASE PRICE OVER NET BOOK VALUE
B7: Equity purchase price ($M) | C7: =Assumptions!C11 -> 15699
B8: (−) HUBS net cash assumed | C8: =-Assumptions!C13 -> -1900
B9: Effective enterprise consideration | C9: =C7+C8 -> 13799 | E9: Equity − net cash
B10: (−) HUBS net tangible book value | C10: -800 | E10: HUBS shareholders' equity ex-goodwill, FY25 10-K
B11: Excess purchase price to allocate | C11: =C9+C10 -> 12999
B14: STEP 2: ALLOCATION TO IDENTIFIABLE INTANGIBLES & GOODWILL
B15: Asset | C15: Allocated ($M) | D15: Life (yrs) | E15: Annual amort ($M) | F15: % of excess
B16: Customer relationships | C16: 2500 | D16: 10 | E16: =C16/D16 -> 250 | F16: =C16/$C$11 -> 0.19232249
B17: Developed technology | C17: 1200 | D17: 5 | E17: =C17/D17 -> 240 | F17: =C17/$C$11 -> 0.092314793
B18: Trade name / brand | C18: 500 | D18: Indef. | E18: , | F18: =C18/$C$11 -> 0.038464497
B19: Deferred rev write-down (memo only) | C19: 200 | D19: , | E19: Y1 revenue haircut, not amortized
B20: Other intangibles | C20: 200 | D20: 3 | E20: =C20/D20 -> 66.666667 | F20: =C20/$C$11 -> 0.015385799
B21: Total identifiable intangibles | C21: =C16+C17+C18+C20 -> 4400 | E21: =E16+E17+E20 -> 556.66667
B22: Goodwill (residual) | C22: =C11-C21 -> 8599 | E22: Not amortized, annual impairment test
B25: STEP 3: INTANGIBLES AMORTIZATION SCHEDULE
B26: Asset | C26: Y1 | D26: Y2 | E26: Y3 | F26: Y4 | G26: Y5 | H26: Y6 | I26: Y7 | J26: Y8
B27: Customer relationships | C27: =$C$16/$D$16 -> 250 | D27: =$C$16/$D$16 -> 250 | E27: =$C$16/$D$16 -> 250 | F27: =$C$16/$D$16 -> 250 | G27: =$C$16/$D$16 -> 250 | H27: =$C$16/$D$16 -> 250 | I27: =$C$16/$D$16 -> 250 | J27: =$C$16/$D$16 -> 250
B28: Developed technology | C28: =$C$17/$D$17 -> 240 | D28: =$C$17/$D$17 -> 240 | E28: =$C$17/$D$17 -> 240 | F28: =$C$17/$D$17 -> 240 | G28: =$C$17/$D$17 -> 240 | H28: 0 | I28: 0 | J28: 0
B29: Deferred rev write-down (not amortized) | C29: 0 | D29: 0 | E29: 0 | F29: 0 | G29: 0 | H29: 0 | I29: 0 | J29: 0
B30: Other intangibles | C30: =$C$20/$D$20 -> 66.666667 | D30: =$C$20/$D$20 -> 66.666667 | E30: =$C$20/$D$20 -> 66.666667 | F30: 0 | G30: 0 | H30: 0 | I30: 0 | J30: 0
B31: Total annual amortization | C31: =SUM(C27:C30) -> 556.66667 | D31: =SUM(D27:D30) -> 556.66667 | E31: =SUM(E27:E30) -> 556.66667 | F31: =SUM(F27:F30) -> 490 | G31: =SUM(G27:G30) -> 490 | H31: =SUM(H27:H30) -> 250 | I31: =SUM(I27:I30) -> 250 | J31: =SUM(J27:J30) -> 250
B34: How to read this tab:
B35: • The way we split up the price across asset categories follows standard practice for software acquisitions.
B36: • Accounting rules require reducing HubSpot's deferred revenue by $200M, which lowers reported Year 1 revenue.
B37: • The yearly expense of writing down these assets shows up in official accounting (GAAP) but is excluded from the non-GAAP numbers companies typically highlight.
B38: • Goodwill stays on the books permanently but is checked yearly to see if its value should be reduced.

Sheet Premiums Paid
B2: PREMIUMS PAID ANALYSIS
B3: Compares the offer price to different recent prices for HubSpot stock, and to premiums paid in similar past deals. Helps judge if the price is fair or leaves room to go higher.
B5: OFFER VS. HUBS HISTORICAL TRADING REFERENCES
B6: Reference price | C6: Price ($) | D6: Implied premium | E6: Source
B7: 1-day prior closing price | C7: 234.5 | D7: =Assumptions!$C$8/C7-1 -> 0.2793177 | E7: HubSpot's closing share price the day before the deal is announced
B8: 5-day VWAP | C8: 237.2 | D8: =Assumptions!$C$8/C8-1 -> 0.26475548 | E8: Average HubSpot price over the past 5 trading days
B9: 30-day VWAP | C9: 239.28 | D9: =Assumptions!$C$8/C9-1 -> 0.25376128 | E9: Average HubSpot price over the past 30 trading days, the most commonly cited reference
B10: 60-day VWAP | C10: 235 | D10: =Assumptions!$C$8/C10-1 -> 0.27659574 | E10: Average HubSpot price over the past 60 trading days
B11: 90-day VWAP | C11: 228.5 | D11: =Assumptions!$C$8/C11-1 -> 0.31291028 | E11: Average HubSpot price over the past 90 trading days
B12: 52-week high | C12: 317 | D12: =Assumptions!$C$8/C12-1 -> -0.05362776 | E12: Highest HubSpot price in the past year
B13: 52-week low | C13: 159 | D13: =Assumptions!$C$8/C13-1 -> 0.88679245 | E13: Lowest HubSpot price in the past year
B14: All-time high (Nov 2021) | C14: 866 | D14: =Assumptions!$C$8/C14-1 -> -0.65357968 | E14: All-time peak during the 2021 software bubble
B16: Median across short-term references (1-day to 90-day) | D16: =MEDIAN(D7:D11) -> 0.27659574
B19: OFFER VS. SAAS PRECEDENT MEDIAN
B20: Proposed offer premium (30-day VWAP) | C20: =Assumptions!C12 -> 0.25376128
B21: Precedent SaaS M&A median premium | C21: ='Precedent Trans'!H14 -> 0.4
B22: Gap to precedent median | C22: =C20-C21 -> -0.14623872
B24: Implied price at precedent median premium | C24: =C9*(1+C21) -> 334.992 | E24: 30-day VWAP × (1 + precedent median premium)
B25: Bidding-room headroom ($/share) | C25: =C24-Assumptions!C8 -> 34.992
B28: How to read this tab:
B29: • We compare the offer to multiple recent stock prices to verify the premium is fair from different angles.
B30: • Proposed 25% premium is below SaaS precedent median (40%), leaves room to increase offer in a competitive process.

Sheet Contribution
B2: CONTRIBUTION ANALYSIS
B3: Shows what percent each side contributes to the combined company on different measures (revenue, profit, customers).
B5: FY2026E CONTRIBUTION TO COMBINED ENTITY
B6: Metric | C6: Salesforce | D6: HubSpot | E6: Combined | F6: HUBS % | G6: HUBS consid. %
B7: Revenue ($M) | C7: 41500 | D7: ='Target Financials'!F7 -> 3705 | E7: =C7+D7 -> 45205 | F7: =D7/E7 -> 0.08195996
B8: EBITDA ($M) | C8: 12000 | D8: ='Target Financials'!F12+'Target Financials'!F7*0.03 -> 852.15 | E8: =C8+D8 -> 12852.15 | F8: =D8/E8 -> 0.066304081
B9: Non-GAAP Op Income ($M) | C9: 11500 | D9: ='Target Financials'!F12 -> 741 | E9: =C9+D9 -> 12241 | F9: =D9/E9 -> 0.06053427
B10: Non-GAAP Net Income ($M) | C10: 9500 | D10: ='Target Financials'!F12*(1-Assumptions!$C$43) -> 585.39 | E10: =C10+D10 -> 10085.39 | F10: =D10/E10 -> 0.058043368
B11: Unlevered FCF ($M) | C11: 10500 | D11: =DCF!C20 -> 377.0865 | E11: =C11+D11 -> 10877.086 | F11: =D11/E11 -> 0.034667969
B12: Customers (000) | C12: 150 | D12: ='Target Financials'!F13 -> 280 | E12: =C12+D12 -> 430 | F12: =D12/E12 -> 0.65116279
B13: Diluted Shares (M) | C13: 1028 | D13: =Assumptions!C10 -> 52.33 | E13: =C13+D13 -> 1080.33 | F13: =D13/E13 -> 0.048438903
B14: Market Cap ($M) | C14: 253000 | D14: =Assumptions!C11 -> 15699 | E14: =C14+D14 -> 268699 | F14: =D14/E14 -> 0.058425971 | G14: =Assumptions!$C$11/(Assumptions!$C$11+253000) -> 0.058425971
B17: Key takeaway
B18: HUBS contributes ~8% of revenue and ~7% of NOPAT but represents only ~6% of consideration, favorable for CRM shareholders.

Sheet Returns
B2: RETURNS ANALYSIS, VALUE CREATION FOR CRM SHAREHOLDERS
B3: Calculates the total long-term value Salesforce shareholders get from doing this deal, after subtracting the premium paid. Positive number means the deal creates value.
B5: NPV OF SYNERGIES (after-tax, at WACC)
B6: ($M) | C6: Y1 | D6: Y2 | E6: Y3 | F6: Y4 | G6: Y5 | H6: Y6 | I6: Y7 | J6: Y8 | K6: Terminal
B7: Pre-tax synergies (run-rate) | C7: =Synergies!C20 -> 310 | D7: =Synergies!D20 -> 770 | E7: =Synergies!E20 -> 1440 | F7: =E7*1.03 -> 1483.2 | G7: =F7*1.03 -> 1527.696 | H7: =G7*1.03 -> 1573.5269 | I7: =H7*1.03 -> 1620.7327 | J7: =I7*1.03 -> 1669.3547 | K7: ,
B8: (−) Tax @ 21% | C8: =-C7*Assumptions!$C$43 -> -65.1 | D8: =-D7*Assumptions!$C$43 -> -161.7 | E8: =-E7*Assumptions!$C$43 -> -302.4 | F8: =-F7*Assumptions!$C$43 -> -311.472 | G8: =-G7*Assumptions!$C$43 -> -320.81616 | H8: =-H7*Assumptions!$C$43 -> -330.44064 | I8: =-I7*Assumptions!$C$43 -> -340.35386 | J8: =-J7*Assumptions!$C$43 -> -350.56448 | K8: ,
B9: After-tax synergies | C9: =C7+C8 -> 244.9 | D9: =D7+D8 -> 608.3 | E9: =E7+E8 -> 1137.6 | F9: =F7+F8 -> 1171.728 | G9: =G7+G8 -> 1206.8798 | H9: =H7+H8 -> 1243.0862 | I9: =I7+I8 -> 1280.3788 | J9: =J7+J8 -> 1318.7902 | K9: ,
B10: (−) Integration costs (after-tax) | C10: =-Assumptions!C35*(1-Assumptions!C43) -> -276.5 | D10: 0 | E10: 0 | F10: 0 | G10: 0 | H10: 0 | I10: 0 | J10: 0 | K10: ,
B11: Net synergy cash flow | C11: =C9+C10 -> -31.6 | D11: =D9+D10 -> 608.3 | E11: =E9+E10 -> 1137.6 | F11: =F9+F10 -> 1171.728 | G11: =G9+G10 -> 1206.8798 | H11: =H9+H10 -> 1243.0862 | I11: =I9+I10 -> 1280.3788 | J11: =J9+J10 -> 1318.7902 | K11: =J9*(1+0.025)/(Assumptions!$C$47-0.025) -> 17932.845
B12: Discount factor | C12: =1/(1+Assumptions!$C$47)^1 -> 0.90877779 | D12: =1/(1+Assumptions!$C$47)^2 -> 0.82587708 | E12: =1/(1+Assumptions!$C$47)^3 -> 0.75053875 | F12: =1/(1+Assumptions!$C$47)^4 -> 0.68207295 | G12: =1/(1+Assumptions!$C$47)^5 -> 0.61985275 | H12: =1/(1+Assumptions!$C$47)^6 -> 0.56330841 | I12: =1/(1+Assumptions!$C$47)^7 -> 0.51192218 | J12: =1/(1+Assumptions!$C$47)^8 -> 0.46522351 | K12: =J12 -> 0.46522351
B13: PV of net synergy cash flow | C13: =C11*C12 -> -28.717378 | D13: =D11*D12 -> 502.38103 | E13: =E11*E12 -> 853.81288 | F13: =F11*F12 -> 799.20397 | G13: =G11*G12 -> 748.08779 | H13: =H11*H12 -> 700.24094 | I13: =I11*I12 -> 655.45432 | J13: =J11*J12 -> 613.5322 | K13: =K11*K12 -> 8342.7812
B16: VALUE CREATION SUMMARY
B18: Sum of PV of explicit-period net synergies | C18: =SUM(C13:J13) -> 4843.9957
B19: PV of terminal synergy value | C19: =K13 -> 8342.7812
B20: Total NPV of synergies | C20: =C18+C19 -> 13186.777
B21: Premium paid above pre-deal market cap | C21: =Assumptions!C11-(Assumptions!C9*Assumptions!C10) -> 3177.4776
B22: Net value creation to CRM shareholders | C22: =C20-C21 -> 10009.299
B23: Net value creation per CRM share ($) | C23: =C22/Assumptions!C54 -> 9.7366725
B24: Value creation as % of premium paid | C24: =C22/C21 -> 3.1500771
B27: How this works:
B28: • Future synergy cash flows are translated back to today's dollars using the same discount rate as the DCF.
B29: • After Year 3, synergies are assumed to grow at a modest 3 percent per year.
B30: • Beyond Year 8, the remaining value assumes 2.5 percent annual growth forever.
B31: • Excludes execution risk haircut, see Risk Factors (Section VII of memo).

Sheet Appendix
B2: APPENDIX, EXTENDED PEER ANALYTICS & PRECEDENT REGRESSION
B3: Extra analysis backing up the main tabs: extended peer data and a statistical regression showing how acquisition multiples relate to target growth rate.
B5: A.1 EXTENDED PEER SCREEN
B6: Company | C6: NTM Rev ($B) | D6: NTM Gr. | E6: GM | F6: Op Margin | G6: FCF Conv. | H6: Rule of 40 | I6: EV/NTM Rev | J6: EV/NTM/Growth
B7: Salesforce (CRM) | C7: 45.7 | D7: 0.1 | E7: 0.78 | F7: 0.32 | G7: 0.95 | H7: =D7+E7 -> 0.88 | I7: 5.4 | J7: =I7/D7 -> 54
B8: ServiceNow (NOW) | C8: 13.5 | D8: 0.19 | E8: 0.8 | F8: 0.3 | G8: 0.92 | H8: =D8+E8 -> 0.99 | I8: 14.5 | J8: =I8/D8 -> 76.315789
B9: Adobe (ADBE) | C9: 24 | D9: 0.1 | E9: 0.89 | F9: 0.38 | G9: 0.98 | H9: =D9+E9 -> 0.99 | I9: 12 | J9: =I9/D9 -> 120
B10: Workday (WDAY) | C10: 9.5 | D10: 0.15 | E10: 0.76 | F10: 0.27 | G10: 0.85 | H10: =D10+E10 -> 0.91 | I10: 7.5 | J10: =I10/D10 -> 50
B11: Atlassian (TEAM) | C11: 5.5 | D11: 0.18 | E11: 0.84 | F11: 0.22 | G11: 0.88 | H11: =D11+E11 -> 1.02 | I11: 11 | J11: =I11/D11 -> 61.111111
B12: Freshworks (FRSH) | C12: 1.07 | D12: 0.16 | E12: 0.83 | F12: 0.06 | G12: 0.65 | H12: =D12+E12 -> 0.99 | I12: 4.6 | J12: =I12/D12 -> 28.75
B13: monday.com (MNDY) | C13: 1.62 | D13: 0.22 | E13: 0.89 | F13: 0.15 | G13: 0.8 | H13: =D13+E13 -> 1.11 | I13: 6.7 | J13: =I13/D13 -> 30.454545
B14: Zendesk (PE) | C14: 1.73 | D14: 0.15 | E14: 0.77 | F14: 0.18 | G14: 0.75 | H14: =D14+E14 -> 0.92 | I14: 5.9 | J14: =I14/D14 -> 39.333333
B15: Braze (BRZE) | C15: 0.59 | D15: 0.21 | E15: 0.69 | F15: 0.05 | G15: 0.6 | H15: =D15+E15 -> 0.9 | I15: 4.9 | J15: =I15/D15 -> 23.333333
B16: Sprout Social (SPT) | C16: 0.42 | D16: 0.18 | E16: 0.74 | F16: 0.1 | G16: 0.7 | H16: =D16+E16 -> 0.92 | I16: 5.2 | J16: =I16/D16 -> 28.888889
B17: Asana (ASAN) | C17: 0.78 | D17: 0.11 | E17: 0.9 | F17: -0.05 | G17: 0.5 | H17: =D17+E17 -> 1.01 | I17: 3.2 | J17: =I17/D17 -> 29.090909
B18: Smartsheet (SMAR) | C18: 1.3 | D18: 0.15 | E18: 0.81 | F18: 0.08 | G18: 0.7 | H18: =D18+E18 -> 0.96 | I18: 4.8 | J18: =I18/D18 -> 32
B20: Peer median | C20: =MEDIAN(C7:C18) -> 1.675 | D20: =MEDIAN(D7:D18) -> 0.155 | E20: =MEDIAN(E7:E18) -> 0.805 | F20: =MEDIAN(F7:F18) -> 0.165 | G20: =MEDIAN(G7:G18) -> 0.775 | H20: =MEDIAN(H7:H18) -> 0.975 | I20: =MEDIAN(I7:I18) -> 5.65 | J20: =MEDIAN(J7:J18) -> 35.666667
B21: HubSpot (HUBS) | C21: 3.71 | D21: 0.18 | E21: 0.85 | F21: 0.2 | G21: 0.85 | H21: =D21+E21 -> 1.03 | I21: 2.9 | J21: =I21/D21 -> 16.111111
B23: GROWTH-ADJUSTED MULTIPLE ANALYSIS
B24: HUBS EV/NTM/Growth | C24: =J21 -> 16.111111
B25: Peer median EV/NTM/Growth | C25: =J20 -> 35.666667
B26: Discount (growth-adjusted) | C26: =C24/C25-1 -> -0.5482866
B27: (Even adjusted for slower growth, HUBS trades at discount)
B31: A.2 PRECEDENT TRANSACTION REGRESSION, EV/NTM Rev vs. Target Growth Rate
B32: Target | C32: Year | D32: Target NTM Growth | E32: EV/NTM Rev | F32: Implied at HUBS growth
B33: Slack | C33: 2021 | D33: 0.35 | E33: 19.5 | F33: =E33*(0.18/D33) -> 10.028571
B34: Tableau | C34: 2019 | D34: 0.18 | E34: 9.2 | F34: =E34*(0.18/D34) -> 9.2
B35: Zendesk | C35: 2023 | D35: 0.16 | E35: 5.4 | F35: =E35*(0.18/D35) -> 6.075
B36: Qualtrics | C36: 2019 | D36: 0.25 | E36: 15.4 | F36: =E36*(0.18/D36) -> 11.088
B37: Ping Identity | C37: 2022 | D37: 0.2 | E37: 7.7 | F37: =E37*(0.18/D37) -> 6.93
B38: Informatica | C38: 2025 | D38: 0.07 | E38: 4.4 | F38: =E38*(0.18/D38) -> 11.314286
B39: Own Company | C39: 2024 | D39: 0.4 | E39: 5.8 | F39: =E39*(0.18/D39) -> 2.61
B41: Regression slope (EV/NTM per 1% growth) | C41: =SLOPE(E33:E39,D33:D39) -> 23.981959
B42: Regression intercept | C42: =INTERCEPT(E33:E39,D33:D39) -> 4.1127209
B43: R-squared | C43: =RSQ(E33:E39,D33:D39) -> 0.2294219
B44: Regression-implied multiple for HUBS at 18% growth | C44: =C41*0.18+C42 -> 8.4294735
B45: Regression-implied EV at HUBS growth | C45: =C44*Assumptions!C19 -> 31231.199
B46: Regression-implied $/share | C46: =(C45+Assumptions!C13)/Assumptions!C10 -> 633.12057
B49: How to read this tab:
B50: • Statistical analysis showing the relationship between how fast a company grows and what multiple acquirers pay.
...
